Workbook

Sheet Sheet1
A1: HELAIAN MATA (SCORESHEET)
A2: BAHAGIAN PILIHAN RAYA NEGERI: N.12 JERAM
A4: JUMLAH PEMILIH : 19,751
A5: Bil | B5: No. Kod Daerah Mengundi | C5: Nama Pusat Mengundi | D5: Nombor Tempat Mengundi | E5: Jumlah Kertas Undi Yang Patut Berada Di Dalam Peti Undi (A) | F5: Bilangan Undian Oleh Pemilih Bagi Setiap Orang Calon Yang Bertanding (B) | J5: Bilangan Kertas Undi Yang Ditolak (C) | K5: Jumlah Kertas Undi Yang Dikeluarkan Kepada Pengundi Tetapi Tidak Dimasukkan Ke Dalam Peti Undi(D)
F6: MOHD SHAID BIN ROSLI | G6: USTAZ MOHD NOOR | H6: CIKGU ZAHAR | I6: Jumlah Undian Oleh Pemilih
A8: 1 | B8: UNDI POS | C8: UNDI POS | D8: 1 | E8: 174 | F8: 38 | G8: 46 | H8: 53 | I8: 137 | J8: 6 | K8: 31
A9: 2 | B9: UNDI AWAL 096/12/00 | C9: RUMAH KELAB IPPD KUALA SELANGOR | D9: 1 | E9: 25 | F9: 0 | G9: 2 | H9: 22 | I9: 24 | J9: 1 | K9: 0
A10: 3 | B10: FELDA BUKIT CHERAKAH | C10: SEKOLAH KEBANGSAAN BUKIT CERAKA | D10: 1 | E10: 323 | F10: 83 | G10: 39 | H10: 200 | I10: 322 | J10: 1 | K10: 0
B11: 096/12/01 | C11: SEKOLAH KEBANGSAAN BUKIT CERAKA | D11: 2 | E11: 632 | F11: 234 | G11: 141 | H11: 253 | I11: 628 | J11: 4 | K11: 0
A12: 4 | B12: BUKIT HIJAU | C12: PEJABAT JKKK KAMPUNG BUKIT HIJAU | D12: 1 | E12: 323 | F12: 34 | G12: 91 | H12: 188 | I12: 313 | J12: 10 | K12: 0
B13: 096/12/02 | C13: PEJABAT JKKK KAMPUNG BUKIT HIJAU | D13: 2 | E13: 447 | F13: 52 | G13: 182 | H13: 212 | I13: 446 | J13: 1 | K13: 0
C14: PEJABAT JKKK KAMPUNG BUKIT HIJAU | D14: 3 | E14: 427 | F14: 102 | G14: 164 | H14: 159 | I14: 425 | J14: 2 | K14: 0
A15: 5 | B15: BUKIT KUCHING TENGAH | C15: DEWAN ORANG RAMAI KAMPUNG BUKIT KUCHING TENGAH | D15: 1 | E15: 311 | F15: 58 | G15: 48 | H15: 200 | I15: 306 | J15: 5 | K15: 0
B16: 096/12/03 | C16: DEWAN ORANG RAMAI KAMPUNG BUKIT KUCHING TENGAH | D16: 2 | E16: 367 | F16: 99 | G16: 99 | H16: 163 | I16: 361 | J16: 6 | K16: 0
A17: 6 | B17: SIMPANG TIGA | C17: SEKOLAH KEBANGSAAN JERAM | D17: 1 | E17: 275 | F17: 117 | G17: 30 | H17: 114 | I17: 261 | J17: 14 | K17: 0
B18: 096/12/04 | C18: SEKOLAH KEBANGSAAN JERAM | D18: 2 | E18: 630 | F18: 253 | G18: 116 | H18: 247 | I18: 616 | J18: 14 | K18: 0
C19: SEKOLAH KEBANGSAAN JERAM | D19: 3 | E19: 580 | F19: 282 | G19: 94 | H19: 199 | I19: 575 | J19: 5 | K19: 0
A20: 7 | B20: JERAM | C20: SEKOLAH KEBANGSAAN JERAM BATU 20 JERAM | D20: 1 | E20: 288 | F20: 113 | G20: 47 | H20: 125 | I20: 285 | J20: 3 | K20: 0
B21: 096/12/05 | C21: SEKOLAH KEBANGSAAN JERAM BATU 20 JERAM | D21: 2 | E21: 368 | F21: 177 | G21: 73 | H21: 116 | I21: 366 | J21: 2 | K21: 0
A22: 8 | B22: SUNGAI SEMBILANG | C22: SEKOLAH RENDAH JENIS KEBANGSAAN (CINA) LIAT CHOON (PUSAT) BATU 17, JERAM | D22: 1 | E22: 281 | F22: 88 | G22: 45 | H22: 139 | I22: 272 | J22: 9 | K22: 0
B23: 096/12/06 | C23: SEKOLAH RENDAH JENIS KEBANGSAAN (CINA) LIAT CHOON (PUSAT) BATU 17, JERAM | D23: 2 | E23: 497 | F23: 155 | G23: 113 | H23: 224 | I23: 492 | J23: 5 | K23: 0
C24: SEKOLAH RENDAH JENIS KEBANGSAAN (CINA) LIAT CHOON (PUSAT) BATU 17, JERAM | D24: 3 | E24: 473 | F24: 181 | G24: 121 | H24: 169 | I24: 471 | J24: 2 | K24: 0
A25: 9 | B25: TAMBAK JAWA | C25: SEKOLAH KEBANGSAAN TAMBAK JAWA | D25: 1 | E25: 297 | F25: 143 | G25: 27 | H25: 118 | I25: 288 | J25: 9 | K25: 0
B26: 096/12/07 | C26: SEKOLAH KEBANGSAAN TAMBAK JAWA | D26: 2 | E26: 573 | F26: 278 | G26: 71 | H26: 216 | I26: 565 | J26: 8 | K26: 0
C27: SEKOLAH KEBANGSAAN TAMBAK JAWA | D27: 3 | E27: 587 | F27: 348 | G27: 101 | H27: 133 | I27: 582 | J27: 5 | K27: 0
A28: 10 | B28: BUKIT CLOH | C28: SEKOLAH JENIS KEBANGSAAN (TAMIL) LADANG BUKIT CHERAKA | D28: 1 | E28: 289 | F28: 142 | G28: 23 | H28: 102 | I28: 267 | J28: 22 | K28: 0
B29: 096/12/08 | C29: SEKOLAH JENIS KEBANGSAAN (TAMIL) LADANG BUKIT CHERAKA | D29: 2 | E29: 541 | F29: 328 | G29: 58 | H29: 146 | I29: 532 | J29: 9 | K29: 0
A30: 11 | B30: BUKIT KERAYONG | C30: SEKOLAH KEBANGSAAN BUKIT KERAYONG | D30: 1 | E30: 326 | F30: 29 | G30: 67 | H30: 224 | I30: 320 | J30: 6 | K30: 0
B31: 096/12/09 | C31: SEKOLAH KEBANGSAAN BUKIT KERAYONG | D31: 2 | E31: 511 | F31: 91 | G31: 183 | H31: 235 | I31: 509 | J31: 2 | K31: 0
C32: SEKOLAH KEBANGSAAN BUKIT KERAYONG | D32: 3 | E32: 502 | F32: 138 | G32: 163 | H32: 197 | I32: 498 | J32: 4 | K32: 0
A33: 12 | B33: JERAM PANTAI 096/12/10 | C33: SEKOLAH RENDAH AGAMA PEKAN JERAM | D33: 1 | E33: 477 | F33: 147 | G33: 127 | H33: 198 | I33: 472 | J33: 5 | K33: 0
A34: 13 | B34: BANDAR PUNCAK ALAM | C34: SEKOLAH KEBANGSAAN PUNCAK ALAM 2 | D34: 1 | E34: 329 | F34: 128 | G34: 68 | H34: 131 | I34: 327 | J34: 2 | K34: 0
B35: 096/12/11 | C35: SEKOLAH KEBANGSAAN PUNCAK ALAM 2 | D35: 2 | E35: 724 | F35: 260 | G35: 271 | H35: 192 | I35: 723 | J35: 1 | K35: 0
C36: SEKOLAH KEBANGSAAN PUNCAK ALAM 2 | D36: 3 | E36: 724 | F36: 234 | G36: 300 | H36: 185 | I36: 719 | J36: 5 | K36: 0
C37: SEKOLAH KEBANGSAAN PUNCAK ALAM 2 | D37: 4 | E37: 704 | F37: 247 | G37: 289 | H37: 166 | I37: 702 | J37: 2 | K37: 0
C38: SEKOLAH KEBANGSAAN PUNCAK ALAM 2 | D38: 5 | E38: 696 | F38: 291 | G38: 258 | H38: 146 | I38: 695 | J38: 1 | K38: 0
C39: SEKOLAH KEBANGSAAN PUNCAK ALAM 2 | D39: 6 | E39: 646 | F39: 334 | G39: 211 | H39: 100 | I39: 645 | J39: 1 | K39: 0
C40: SEKOLAH KEBANGSAAN PUNCAK ALAM 2 | D40: 7 | E40: 663 | F40: 337 | G40: 210 | H40: 114 | I40: 661 | J40: 2 | K40: 0
C41: SEKOLAH KEBANGSAAN PUNCAK ALAM 2 | D41: 8 | E41: 685 | F41: 329 | G41: 231 | H41: 125 | I41: 685 | J41: 0 | K41: 0
A42: 14 | B42: TUAN MEE | C42: SEKOLAH JENIS KEBANGSAAN (TAMIL) LADANG TUAN MEE | D42: 1 | E42: 284 | F42: 174 | G42: 23 | H42: 82 | I42: 279 | J42: 5 | K42: 0
...

Sheet Sheet2
A1: {=_xlfn.UNIQUE(_xlfn._xlws.FILTER(Sheet1!C:C, Sheet1!C:C <>""))} -> Nama Pusat Mengundi | B1: JUM. SALURAN | C1: JUM. PEMILIH | D1: JUM. UNDI YB SHAID | E1: PERC.
A2: UNDI POS | B2: =COUNTIF(Sheet1!C:C,$A2) -> 1 | C2: =SUMIFS(Sheet1!E:E,Sheet1!C:C, $A2) -> 174 | D2: =SUMIFS(Sheet1!F:F,Sheet1!C:C, $A2) -> 38 | E2: =SUM(D2/C2) -> 0.2183908
A3: RUMAH KELAB IPPD KUALA SELANGOR | B3: =COUNTIF(Sheet1!C:C,$A3) -> 1 | C3: =SUMIFS(Sheet1!E:E,Sheet1!C:C, $A3) -> 25 | D3: =SUMIFS(Sheet1!F:F,Sheet1!C:C, $A3) -> 0 | E3: =SUM(D3/C3) -> 0
A4: SEKOLAH KEBANGSAAN BUKIT CERAKA | B4: =COUNTIF(Sheet1!C:C,$A4) -> 2 | C4: =SUMIFS(Sheet1!E:E,Sheet1!C:C, $A4) -> 955 | D4: =SUMIFS(Sheet1!F:F,Sheet1!C:C, $A4) -> 317 | E4: =SUM(D4/C4) -> 0.33193717
A5: PEJABAT JKKK KAMPUNG BUKIT HIJAU | B5: =COUNTIF(Sheet1!C:C,$A5) -> 3 | C5: =SUMIFS(Sheet1!E:E,Sheet1!C:C, $A5) -> 1197 | D5: =SUMIFS(Sheet1!F:F,Sheet1!C:C, $A5) -> 188 | E5: =SUM(D5/C5) -> 0.15705931
A6: DEWAN ORANG RAMAI KAMPUNG BUKIT KUCHING TENGAH | B6: =COUNTIF(Sheet1!C:C,$A6) -> 2 | C6: =SUMIFS(Sheet1!E:E,Sheet1!C:C, $A6) -> 678 | D6: =SUMIFS(Sheet1!F:F,Sheet1!C:C, $A6) -> 157 | E6: =SUM(D6/C6) -> 0.23156342
A7: SEKOLAH KEBANGSAAN JERAM | B7: =COUNTIF(Sheet1!C:C,$A7) -> 3 | C7: =SUMIFS(Sheet1!E:E,Sheet1!C:C, $A7) -> 1485 | D7: =SUMIFS(Sheet1!F:F,Sheet1!C:C, $A7) -> 652 | E7: =SUM(D7/C7) -> 0.43905724
A8: SEKOLAH KEBANGSAAN JERAM BATU 20 JERAM | B8: =COUNTIF(Sheet1!C:C,$A8) -> 2 | C8: =SUMIFS(Sheet1!E:E,Sheet1!C:C, $A8) -> 656 | D8: =SUMIFS(Sheet1!F:F,Sheet1!C:C, $A8) -> 290 | E8: =SUM(D8/C8) -> 0.44207317
A9: SEKOLAH RENDAH JENIS KEBANGSAAN (CINA) LIAT CHOON (PUSAT) BATU 17, JERAM | B9: =COUNTIF(Sheet1!C:C,$A9) -> 3 | C9: =SUMIFS(Sheet1!E:E,Sheet1!C:C, $A9) -> 1251 | D9: =SUMIFS(Sheet1!F:F,Sheet1!C:C, $A9) -> 424 | E9: =SUM(D9/C9) -> 0.33892886
A10: SEKOLAH KEBANGSAAN TAMBAK JAWA | B10: =COUNTIF(Sheet1!C:C,$A10) -> 3 | C10: =SUMIFS(Sheet1!E:E,Sheet1!C:C, $A10) -> 1457 | D10: =SUMIFS(Sheet1!F:F,Sheet1!C:C, $A10) -> 769 | E10: =SUM(D10/C10) -> 0.52779684
A11: SEKOLAH JENIS KEBANGSAAN (TAMIL) LADANG BUKIT CHERAKA | B11: =COUNTIF(Sheet1!C:C,$A11) -> 2 | C11: =SUMIFS(Sheet1!E:E,Sheet1!C:C, $A11) -> 830 | D11: =SUMIFS(Sheet1!F:F,Sheet1!C:C, $A11) -> 470 | E11: =SUM(D11/C11) -> 0.56626506
A12: SEKOLAH KEBANGSAAN BUKIT KERAYONG | B12: =COUNTIF(Sheet1!C:C,$A12) -> 3 | C12: =SUMIFS(Sheet1!E:E,Sheet1!C:C, $A12) -> 1339 | D12: =SUMIFS(Sheet1!F:F,Sheet1!C:C, $A12) -> 258 | E12: =SUM(D12/C12) -> 0.19268111
A13: SEKOLAH RENDAH AGAMA PEKAN JERAM | B13: =COUNTIF(Sheet1!C:C,$A13) -> 1 | C13: =SUMIFS(Sheet1!E:E,Sheet1!C:C, $A13) -> 477 | D13: =SUMIFS(Sheet1!F:F,Sheet1!C:C, $A13) -> 147 | E13: =SUM(D13/C13) -> 0.3081761
... A15: SEKOLAH JENIS KEBANGSAAN (TAMIL) LADANG TUAN MEE | B15: =COUNTIF(Sheet1!C:C,$A15) -> 4 | C15: =SUMIFS(Sheet1!E:E,Sheet1!C:C, $A15) -> 1839 | D15: =SUMIFS(Sheet1!F:F,Sheet1!C:C, $A15) -> 1217 | E15: =SUM(D15/C15) -> 0.6617727
C17: =SUM(C2:C15) -> 17534 | D17: =SUM(D2:D15) -> 7087 | E17: =SUM(D17/C17) -> 0.40418615
